<?xml version="1.0" encoding="UTF-8"?>
<!-- Generated by org.testng.reporters.JUnitReportReporter -->
<testsuite hostname="DESKTOP-R2K6MVF" failures="1" tests="12" name="edu.poly.model.HocVienNGTest" time="0.006" errors="4" timestamp="2021-04-27T09:23:07 ICT" skipped="0">
  <testcase classname="edu.poly.model.HocVienNGTest" name="testGetMaKH" time="0.000"/>
  <system-out/>
  <testcase classname="edu.poly.model.HocVienNGTest" name="testGetDiem" time="0.002"/>
  <system-out/>
  <testcase classname="edu.poly.model.HocVienNGTest" name="testSetMaHVWithNegative" time="0.000">
    <error message="
Method HocVienNGTest.testSetMaHVWithNegative()[pri:0, instance:edu.poly.model.HocVienNGTest@3c35c345] should have thrown an exception of type class java.lang.Exception" type="org.testng.TestException">
      <![CDATA[org.testng.TestException: 
Method HocVienNGTest.testSetMaHVWithNegative()[pri:0, instance:edu.poly.model.HocVienNGTest@3c35c345] should have thrown an exception of type class java.lang.Exception
at org.testng.internal.ExpectedExceptionsHolder.noException(ExpectedExceptionsHolder.java:82)
at org.testng.internal.TestInvoker.considerExceptions(TestInvoker.java:741)
at org.testng.internal.TestInvoker.invokeMethod(TestInvoker.java:629)
at org.testng.internal.TestInvoker.invokeTestMethod(TestInvoker.java:173)
at org.testng.internal.MethodRunner.runInSequence(MethodRunner.java:46)
at org.testng.internal.TestInvoker$MethodInvocationAgent.invoke(TestInvoker.java:816)
at org.testng.internal.TestInvoker.invokeTestMethods(TestInvoker.java:146)
at org.testng.internal.TestMethodWorker.invokeTestMethods(TestMethodWorker.java:146)
at org.testng.internal.TestMethodWorker.run(TestMethodWorker.java:128)
at java.base/java.util.ArrayList.forEach(ArrayList.java:1540)
at org.testng.TestRunner.privateRun(TestRunner.java:766)
at org.testng.TestRunner.run(TestRunner.java:587)
at org.testng.SuiteRunner.runTest(SuiteRunner.java:384)
at org.testng.SuiteRunner.runSequentially(SuiteRunner.java:378)
at org.testng.SuiteRunner.privateRun(SuiteRunner.java:337)
at org.testng.SuiteRunner.run(SuiteRunner.java:286)
at org.testng.SuiteRunnerWorker.runSuite(SuiteRunnerWorker.java:53)
at org.testng.SuiteRunnerWorker.run(SuiteRunnerWorker.java:96)
at org.testng.TestNG.runSuitesSequentially(TestNG.java:1187)
at org.testng.TestNG.runSuitesLocally(TestNG.java:1109)
at org.testng.TestNG.runSuites(TestNG.java:1039)
at org.testng.TestNG.run(TestNG.java:1007)
at org.apache.maven.surefire.testng.TestNGExecutor.run(TestNGExecutor.java:77)
at org.apache.maven.surefire.testng.TestNGDirectoryTestSuite.executeMulti(TestNGDirectoryTestSuite.java:159)
at org.apache.maven.surefire.testng.TestNGDirectoryTestSuite.execute(TestNGDirectoryTestSuite.java:99)
at org.apache.maven.surefire.testng.TestNGProvider.invoke(TestNGProvider.java:106)
at java.base/jdk.internal.reflect.NativeMethodAccessorImpl.invoke0(Native Method)
at java.base/jdk.internal.reflect.NativeMethodAccessorImpl.invoke(NativeMethodAccessorImpl.java:62)
at java.base/jdk.internal.reflect.DelegatingMethodAccessorImpl.invoke(DelegatingMethodAccessorImpl.java:43)
at java.base/java.lang.reflect.Method.invoke(Method.java:566)
at org.apache.maven.surefire.util.ReflectionUtils.invokeMethodWithArray(ReflectionUtils.java:189)
at org.apache.maven.surefire.booter.ProviderFactory$ProviderProxy.invoke(ProviderFactory.java:165)
at org.apache.maven.surefire.booter.ProviderFactory.invokeProvider(ProviderFactory.java:85)
at org.apache.maven.surefire.booter.ForkedBooter.runSuitesInProcess(ForkedBooter.java:115)
at org.apache.maven.surefire.booter.ForkedBooter.main(ForkedBooter.java:75)
]]>
    </error>
  </testcase> <!-- testSetMaHVWithNegative -->
  <system-out/>
  <testcase classname="edu.poly.model.HocVienNGTest" name="testGetMaHV" time="0.000"/>
  <system-out/>
  <testcase classname="edu.poly.model.HocVienNGTest" name="testSetDiemWithNegative" time="0.000">
    <error message="
Method HocVienNGTest.testSetDiemWithNegative()[pri:0, instance:edu.poly.model.HocVienNGTest@3c35c345] should have thrown an exception of type class java.lang.Exception" type="org.testng.TestException">
      <![CDATA[org.testng.TestException: 
Method HocVienNGTest.testSetDiemWithNegative()[pri:0, instance:edu.poly.model.HocVienNGTest@3c35c345] should have thrown an exception of type class java.lang.Exception
at org.testng.internal.ExpectedExceptionsHolder.noException(ExpectedExceptionsHolder.java:82)
at org.testng.internal.TestInvoker.considerExceptions(TestInvoker.java:741)
at org.testng.internal.TestInvoker.invokeMethod(TestInvoker.java:629)
at org.testng.internal.TestInvoker.invokeTestMethod(TestInvoker.java:173)
at org.testng.internal.MethodRunner.runInSequence(MethodRunner.java:46)
at org.testng.internal.TestInvoker$MethodInvocationAgent.invoke(TestInvoker.java:816)
at org.testng.internal.TestInvoker.invokeTestMethods(TestInvoker.java:146)
at org.testng.internal.TestMethodWorker.invokeTestMethods(TestMethodWorker.java:146)
at org.testng.internal.TestMethodWorker.run(TestMethodWorker.java:128)
at java.base/java.util.ArrayList.forEach(ArrayList.java:1540)
at org.testng.TestRunner.privateRun(TestRunner.java:766)
at org.testng.TestRunner.run(TestRunner.java:587)
at org.testng.SuiteRunner.runTest(SuiteRunner.java:384)
at org.testng.SuiteRunner.runSequentially(SuiteRunner.java:378)
at org.testng.SuiteRunner.privateRun(SuiteRunner.java:337)
at org.testng.SuiteRunner.run(SuiteRunner.java:286)
at org.testng.SuiteRunnerWorker.runSuite(SuiteRunnerWorker.java:53)
at org.testng.SuiteRunnerWorker.run(SuiteRunnerWorker.java:96)
at org.testng.TestNG.runSuitesSequentially(TestNG.java:1187)
at org.testng.TestNG.runSuitesLocally(TestNG.java:1109)
at org.testng.TestNG.runSuites(TestNG.java:1039)
at org.testng.TestNG.run(TestNG.java:1007)
at org.apache.maven.surefire.testng.TestNGExecutor.run(TestNGExecutor.java:77)
at org.apache.maven.surefire.testng.TestNGDirectoryTestSuite.executeMulti(TestNGDirectoryTestSuite.java:159)
at org.apache.maven.surefire.testng.TestNGDirectoryTestSuite.execute(TestNGDirectoryTestSuite.java:99)
at org.apache.maven.surefire.testng.TestNGProvider.invoke(TestNGProvider.java:106)
at java.base/jdk.internal.reflect.NativeMethodAccessorImpl.invoke0(Native Method)
at java.base/jdk.internal.reflect.NativeMethodAccessorImpl.invoke(NativeMethodAccessorImpl.java:62)
at java.base/jdk.internal.reflect.DelegatingMethodAccessorImpl.invoke(DelegatingMethodAccessorImpl.java:43)
at java.base/java.lang.reflect.Method.invoke(Method.java:566)
at org.apache.maven.surefire.util.ReflectionUtils.invokeMethodWithArray(ReflectionUtils.java:189)
at org.apache.maven.surefire.booter.ProviderFactory$ProviderProxy.invoke(ProviderFactory.java:165)
at org.apache.maven.surefire.booter.ProviderFactory.invokeProvider(ProviderFactory.java:85)
at org.apache.maven.surefire.booter.ForkedBooter.runSuitesInProcess(ForkedBooter.java:115)
at org.apache.maven.surefire.booter.ForkedBooter.main(ForkedBooter.java:75)
]]>
    </error>
  </testcase> <!-- testSetDiemWithNegative -->
  <system-out/>
  <testcase classname="edu.poly.model.HocVienNGTest" name="testGetMaNH" time="0.001">
    <failure message="expected [] but found [null]" type="java.lang.AssertionError">
      <![CDATA[java.lang.AssertionError: expected [] but found [null]
at org.testng.Assert.fail(Assert.java:97)
at org.testng.Assert.failNotEquals(Assert.java:969)
at org.testng.Assert.assertEqualsImpl(Assert.java:131)
at org.testng.Assert.assertEquals(Assert.java:118)
at org.testng.Assert.assertEquals(Assert.java:575)
at org.testng.Assert.assertEquals(Assert.java:585)
at edu.poly.model.HocVienNGTest.testGetMaNH(HocVienNGTest.java:111)
at java.base/jdk.internal.reflect.NativeMethodAccessorImpl.invoke0(Native Method)
at java.base/jdk.internal.reflect.NativeMethodAccessorImpl.invoke(NativeMethodAccessorImpl.java:62)
at java.base/jdk.internal.reflect.DelegatingMethodAccessorImpl.invoke(DelegatingMethodAccessorImpl.java:43)
at java.base/java.lang.reflect.Method.invoke(Method.java:566)
at org.testng.internal.MethodInvocationHelper.invokeMethod(MethodInvocationHelper.java:134)
at org.testng.internal.TestInvoker.invokeMethod(TestInvoker.java:597)
at org.testng.internal.TestInvoker.invokeTestMethod(TestInvoker.java:173)
at org.testng.internal.MethodRunner.runInSequence(MethodRunner.java:46)
at org.testng.internal.TestInvoker$MethodInvocationAgent.invoke(TestInvoker.java:816)
at org.testng.internal.TestInvoker.invokeTestMethods(TestInvoker.java:146)
at org.testng.internal.TestMethodWorker.invokeTestMethods(TestMethodWorker.java:146)
at org.testng.internal.TestMethodWorker.run(TestMethodWorker.java:128)
at java.base/java.util.ArrayList.forEach(ArrayList.java:1540)
at org.testng.TestRunner.privateRun(TestRunner.java:766)
at org.testng.TestRunner.run(TestRunner.java:587)
at org.testng.SuiteRunner.runTest(SuiteRunner.java:384)
at org.testng.SuiteRunner.runSequentially(SuiteRunner.java:378)
at org.testng.SuiteRunner.privateRun(SuiteRunner.java:337)
at org.testng.SuiteRunner.run(SuiteRunner.java:286)
at org.testng.SuiteRunnerWorker.runSuite(SuiteRunnerWorker.java:53)
at org.testng.SuiteRunnerWorker.run(SuiteRunnerWorker.java:96)
at org.testng.TestNG.runSuitesSequentially(TestNG.java:1187)
at org.testng.TestNG.runSuitesLocally(TestNG.java:1109)
at org.testng.TestNG.runSuites(TestNG.java:1039)
at org.testng.TestNG.run(TestNG.java:1007)
at org.apache.maven.surefire.testng.TestNGExecutor.run(TestNGExecutor.java:77)
at org.apache.maven.surefire.testng.TestNGDirectoryTestSuite.executeMulti(TestNGDirectoryTestSuite.java:159)
at org.apache.maven.surefire.testng.TestNGDirectoryTestSuite.execute(TestNGDirectoryTestSuite.java:99)
at org.apache.maven.surefire.testng.TestNGProvider.invoke(TestNGProvider.java:106)
at java.base/jdk.internal.reflect.NativeMethodAccessorImpl.invoke0(Native Method)
at java.base/jdk.internal.reflect.NativeMethodAccessorImpl.invoke(NativeMethodAccessorImpl.java:62)
at java.base/jdk.internal.reflect.DelegatingMethodAccessorImpl.invoke(DelegatingMethodAccessorImpl.java:43)
at java.base/java.lang.reflect.Method.invoke(Method.java:566)
at org.apache.maven.surefire.util.ReflectionUtils.invokeMethodWithArray(ReflectionUtils.java:189)
at org.apache.maven.surefire.booter.ProviderFactory$ProviderProxy.invoke(ProviderFactory.java:165)
at org.apache.maven.surefire.booter.ProviderFactory.invokeProvider(ProviderFactory.java:85)
at org.apache.maven.surefire.booter.ForkedBooter.runSuitesInProcess(ForkedBooter.java:115)
at org.apache.maven.surefire.booter.ForkedBooter.main(ForkedBooter.java:75)
]]>
    </failure>
  </testcase> <!-- testGetMaNH -->
  <system-out/>
  <testcase classname="edu.poly.model.HocVienNGTest" name="testSetDiemWithLarge" time="0.000">
    <error message="
Method HocVienNGTest.testSetDiemWithLarge()[pri:0, instance:edu.poly.model.HocVienNGTest@3c35c345] should have thrown an exception of type class java.lang.Exception" type="org.testng.TestException">
      <![CDATA[org.testng.TestException: 
Method HocVienNGTest.testSetDiemWithLarge()[pri:0, instance:edu.poly.model.HocVienNGTest@3c35c345] should have thrown an exception of type class java.lang.Exception
at org.testng.internal.ExpectedExceptionsHolder.noException(ExpectedExceptionsHolder.java:82)
at org.testng.internal.TestInvoker.considerExceptions(TestInvoker.java:741)
at org.testng.internal.TestInvoker.invokeMethod(TestInvoker.java:629)
at org.testng.internal.TestInvoker.invokeTestMethod(TestInvoker.java:173)
at org.testng.internal.MethodRunner.runInSequence(MethodRunner.java:46)
at org.testng.internal.TestInvoker$MethodInvocationAgent.invoke(TestInvoker.java:816)
at org.testng.internal.TestInvoker.invokeTestMethods(TestInvoker.java:146)
at org.testng.internal.TestMethodWorker.invokeTestMethods(TestMethodWorker.java:146)
at org.testng.internal.TestMethodWorker.run(TestMethodWorker.java:128)
at java.base/java.util.ArrayList.forEach(ArrayList.java:1540)
at org.testng.TestRunner.privateRun(TestRunner.java:766)
at org.testng.TestRunner.run(TestRunner.java:587)
at org.testng.SuiteRunner.runTest(SuiteRunner.java:384)
at org.testng.SuiteRunner.runSequentially(SuiteRunner.java:378)
at org.testng.SuiteRunner.privateRun(SuiteRunner.java:337)
at org.testng.SuiteRunner.run(SuiteRunner.java:286)
at org.testng.SuiteRunnerWorker.runSuite(SuiteRunnerWorker.java:53)
at org.testng.SuiteRunnerWorker.run(SuiteRunnerWorker.java:96)
at org.testng.TestNG.runSuitesSequentially(TestNG.java:1187)
at org.testng.TestNG.runSuitesLocally(TestNG.java:1109)
at org.testng.TestNG.runSuites(TestNG.java:1039)
at org.testng.TestNG.run(TestNG.java:1007)
at org.apache.maven.surefire.testng.TestNGExecutor.run(TestNGExecutor.java:77)
at org.apache.maven.surefire.testng.TestNGDirectoryTestSuite.executeMulti(TestNGDirectoryTestSuite.java:159)
at org.apache.maven.surefire.testng.TestNGDirectoryTestSuite.execute(TestNGDirectoryTestSuite.java:99)
at org.apache.maven.surefire.testng.TestNGProvider.invoke(TestNGProvider.java:106)
at java.base/jdk.internal.reflect.NativeMethodAccessorImpl.invoke0(Native Method)
at java.base/jdk.internal.reflect.NativeMethodAccessorImpl.invoke(NativeMethodAccessorImpl.java:62)
at java.base/jdk.internal.reflect.DelegatingMethodAccessorImpl.invoke(DelegatingMethodAccessorImpl.java:43)
at java.base/java.lang.reflect.Method.invoke(Method.java:566)
at org.apache.maven.surefire.util.ReflectionUtils.invokeMethodWithArray(ReflectionUtils.java:189)
at org.apache.maven.surefire.booter.ProviderFactory$ProviderProxy.invoke(ProviderFactory.java:165)
at org.apache.maven.surefire.booter.ProviderFactory.invokeProvider(ProviderFactory.java:85)
at org.apache.maven.surefire.booter.ForkedBooter.runSuitesInProcess(ForkedBooter.java:115)
at org.apache.maven.surefire.booter.ForkedBooter.main(ForkedBooter.java:75)
]]>
    </error>
  </testcase> <!-- testSetDiemWithLarge -->
  <system-out/>
  <testcase classname="edu.poly.model.HocVienNGTest" name="testSetDiemWithValid" time="0.000"/>
  <system-out/>
  <testcase classname="edu.poly.model.HocVienNGTest" name="testSetMaNH" time="0.001"/>
  <system-out/>
  <testcase classname="edu.poly.model.HocVienNGTest" name="testSetMaKHWithNegative" time="0.000">
    <error message="
Method HocVienNGTest.testSetMaKHWithNegative()[pri:0, instance:edu.poly.model.HocVienNGTest@3c35c345] should have thrown an exception of type class java.lang.Exception" type="org.testng.TestException">
      <![CDATA[org.testng.TestException: 
Method HocVienNGTest.testSetMaKHWithNegative()[pri:0, instance:edu.poly.model.HocVienNGTest@3c35c345] should have thrown an exception of type class java.lang.Exception
at org.testng.internal.ExpectedExceptionsHolder.noException(ExpectedExceptionsHolder.java:82)
at org.testng.internal.TestInvoker.considerExceptions(TestInvoker.java:741)
at org.testng.internal.TestInvoker.invokeMethod(TestInvoker.java:629)
at org.testng.internal.TestInvoker.invokeTestMethod(TestInvoker.java:173)
at org.testng.internal.MethodRunner.runInSequence(MethodRunner.java:46)
at org.testng.internal.TestInvoker$MethodInvocationAgent.invoke(TestInvoker.java:816)
at org.testng.internal.TestInvoker.invokeTestMethods(TestInvoker.java:146)
at org.testng.internal.TestMethodWorker.invokeTestMethods(TestMethodWorker.java:146)
at org.testng.internal.TestMethodWorker.run(TestMethodWorker.java:128)
at java.base/java.util.ArrayList.forEach(ArrayList.java:1540)
at org.testng.TestRunner.privateRun(TestRunner.java:766)
at org.testng.TestRunner.run(TestRunner.java:587)
at org.testng.SuiteRunner.runTest(SuiteRunner.java:384)
at org.testng.SuiteRunner.runSequentially(SuiteRunner.java:378)
at org.testng.SuiteRunner.privateRun(SuiteRunner.java:337)
at org.testng.SuiteRunner.run(SuiteRunner.java:286)
at org.testng.SuiteRunnerWorker.runSuite(SuiteRunnerWorker.java:53)
at org.testng.SuiteRunnerWorker.run(SuiteRunnerWorker.java:96)
at org.testng.TestNG.runSuitesSequentially(TestNG.java:1187)
at org.testng.TestNG.runSuitesLocally(TestNG.java:1109)
at org.testng.TestNG.runSuites(TestNG.java:1039)
at org.testng.TestNG.run(TestNG.java:1007)
at org.apache.maven.surefire.testng.TestNGExecutor.run(TestNGExecutor.java:77)
at org.apache.maven.surefire.testng.TestNGDirectoryTestSuite.executeMulti(TestNGDirectoryTestSuite.java:159)
at org.apache.maven.surefire.testng.TestNGDirectoryTestSuite.execute(TestNGDirectoryTestSuite.java:99)
at org.apache.maven.surefire.testng.TestNGProvider.invoke(TestNGProvider.java:106)
at java.base/jdk.internal.reflect.NativeMethodAccessorImpl.invoke0(Native Method)
at java.base/jdk.internal.reflect.NativeMethodAccessorImpl.invoke(NativeMethodAccessorImpl.java:62)
at java.base/jdk.internal.reflect.DelegatingMethodAccessorImpl.invoke(DelegatingMethodAccessorImpl.java:43)
at java.base/java.lang.reflect.Method.invoke(Method.java:566)
at org.apache.maven.surefire.util.ReflectionUtils.invokeMethodWithArray(ReflectionUtils.java:189)
at org.apache.maven.surefire.booter.ProviderFactory$ProviderProxy.invoke(ProviderFactory.java:165)
at org.apache.maven.surefire.booter.ProviderFactory.invokeProvider(ProviderFactory.java:85)
at org.apache.maven.surefire.booter.ForkedBooter.runSuitesInProcess(ForkedBooter.java:115)
at org.apache.maven.surefire.booter.ForkedBooter.main(ForkedBooter.java:75)
]]>
    </error>
  </testcase> <!-- testSetMaKHWithNegative -->
  <system-out/>
  <testcase classname="edu.poly.model.HocVienNGTest" name="testSetMaKHWithValid" time="0.002"/>
  <system-out/>
  <testcase classname="edu.poly.model.HocVienNGTest" name="testSetMaHVWithValid" time="0.000"/>
  <system-out/>
</testsuite> <!-- edu.poly.model.HocVienNGTest -->
