<?xml version="1.0" encoding="UTF-8"?>
<!-- Generated by org.testng.reporters.JUnitReportReporter -->
<testsuite hostname="DESKTOP-R2K6MVF" failures="0" tests="11" name="edu.poly.dao.NhanVienDaoNGTest" time="0.802" errors="3" timestamp="2021-04-27T09:23:07 ICT" skipped="0">
  <testcase classname="edu.poly.dao.NhanVienDaoNGTest" name="testInsertWithValidModel" time="0.001"/>
  <system-out/>
  <testcase classname="edu.poly.dao.NhanVienDaoNGTest" name="testDeleteWithNullMahv" time="0.005">
    <error message="
Method NhanVienDaoNGTest.testDeleteWithNullMahv()[pri:0, instance:edu.poly.dao.NhanVienDaoNGTest_$$_jvstabe_0@3ed03652] should have thrown an exception of type class java.lang.Exception" type="org.testng.TestException">
      <![CDATA[org.testng.TestException: 
Method NhanVienDaoNGTest.testDeleteWithNullMahv()[pri:0, instance:edu.poly.dao.NhanVienDaoNGTest_$$_jvstabe_0@3ed03652] should have thrown an exception of type class java.lang.Exception
at org.testng.internal.ExpectedExceptionsHolder.noException(ExpectedExceptionsHolder.java:82)
at org.testng.internal.TestInvoker.considerExceptions(TestInvoker.java:741)
at org.testng.internal.TestInvoker.invokeMethod(TestInvoker.java:629)
at org.testng.internal.TestInvoker.invokeTestMethod(TestInvoker.java:173)
at org.testng.internal.MethodRunner.runInSequence(MethodRunner.java:46)
at org.testng.internal.TestInvoker$MethodInvocationAgent.invoke(TestInvoker.java:816)
at org.testng.internal.TestInvoker.invokeTestMethods(TestInvoker.java:146)
at org.testng.internal.TestMethodWorker.invokeTestMethods(TestMethodWorker.java:146)
at org.testng.internal.TestMethodWorker.run(TestMethodWorker.java:128)
at java.base/java.util.ArrayList.forEach(ArrayList.java:1540)
at org.testng.TestRunner.privateRun(TestRunner.java:766)
at org.testng.TestRunner.run(TestRunner.java:587)
at org.testng.SuiteRunner.runTest(SuiteRunner.java:384)
at org.testng.SuiteRunner.runSequentially(SuiteRunner.java:378)
at org.testng.SuiteRunner.privateRun(SuiteRunner.java:337)
at org.testng.SuiteRunner.run(SuiteRunner.java:286)
at org.testng.SuiteRunnerWorker.runSuite(SuiteRunnerWorker.java:53)
at org.testng.SuiteRunnerWorker.run(SuiteRunnerWorker.java:96)
at org.testng.TestNG.runSuitesSequentially(TestNG.java:1187)
at org.testng.TestNG.runSuitesLocally(TestNG.java:1109)
at org.testng.TestNG.runSuites(TestNG.java:1039)
at org.testng.TestNG.run(TestNG.java:1007)
at org.apache.maven.surefire.testng.TestNGExecutor.run(TestNGExecutor.java:77)
at org.apache.maven.surefire.testng.TestNGDirectoryTestSuite.executeMulti(TestNGDirectoryTestSuite.java:159)
at org.apache.maven.surefire.testng.TestNGDirectoryTestSuite.execute(TestNGDirectoryTestSuite.java:99)
at org.apache.maven.surefire.testng.TestNGProvider.invoke(TestNGProvider.java:106)
at java.base/jdk.internal.reflect.NativeMethodAccessorImpl.invoke0(Native Method)
at java.base/jdk.internal.reflect.NativeMethodAccessorImpl.invoke(NativeMethodAccessorImpl.java:62)
at java.base/jdk.internal.reflect.DelegatingMethodAccessorImpl.invoke(DelegatingMethodAccessorImpl.java:43)
at java.base/java.lang.reflect.Method.invoke(Method.java:566)
at org.apache.maven.surefire.util.ReflectionUtils.invokeMethodWithArray(ReflectionUtils.java:189)
at org.apache.maven.surefire.booter.ProviderFactory$ProviderProxy.invoke(ProviderFactory.java:165)
at org.apache.maven.surefire.booter.ProviderFactory.invokeProvider(ProviderFactory.java:85)
at org.apache.maven.surefire.booter.ForkedBooter.runSuitesInProcess(ForkedBooter.java:115)
at org.apache.maven.surefire.booter.ForkedBooter.main(ForkedBooter.java:75)
]]>
    </error>
  </testcase> <!-- testDeleteWithNullMahv -->
  <system-out/>
  <testcase classname="edu.poly.dao.NhanVienDaoNGTest" name="testFindByIdWithNotFound" time="0.002"/>
  <system-out/>
  <testcase classname="edu.poly.dao.NhanVienDaoNGTest" name="testInsertWithEmptyModel" time="0.003">
    <error message="
Method NhanVienDaoNGTest.testInsertWithEmptyModel()[pri:0, instance:edu.poly.dao.NhanVienDaoNGTest_$$_jvstabe_0@3ed03652] should have thrown an exception of type class java.lang.Exception" type="org.testng.TestException">
      <![CDATA[org.testng.TestException: 
Method NhanVienDaoNGTest.testInsertWithEmptyModel()[pri:0, instance:edu.poly.dao.NhanVienDaoNGTest_$$_jvstabe_0@3ed03652] should have thrown an exception of type class java.lang.Exception
at org.testng.internal.ExpectedExceptionsHolder.noException(ExpectedExceptionsHolder.java:82)
at org.testng.internal.TestInvoker.considerExceptions(TestInvoker.java:741)
at org.testng.internal.TestInvoker.invokeMethod(TestInvoker.java:629)
at org.testng.internal.TestInvoker.invokeTestMethod(TestInvoker.java:173)
at org.testng.internal.MethodRunner.runInSequence(MethodRunner.java:46)
at org.testng.internal.TestInvoker$MethodInvocationAgent.invoke(TestInvoker.java:816)
at org.testng.internal.TestInvoker.invokeTestMethods(TestInvoker.java:146)
at org.testng.internal.TestMethodWorker.invokeTestMethods(TestMethodWorker.java:146)
at org.testng.internal.TestMethodWorker.run(TestMethodWorker.java:128)
at java.base/java.util.ArrayList.forEach(ArrayList.java:1540)
at org.testng.TestRunner.privateRun(TestRunner.java:766)
at org.testng.TestRunner.run(TestRunner.java:587)
at org.testng.SuiteRunner.runTest(SuiteRunner.java:384)
at org.testng.SuiteRunner.runSequentially(SuiteRunner.java:378)
at org.testng.SuiteRunner.privateRun(SuiteRunner.java:337)
at org.testng.SuiteRunner.run(SuiteRunner.java:286)
at org.testng.SuiteRunnerWorker.runSuite(SuiteRunnerWorker.java:53)
at org.testng.SuiteRunnerWorker.run(SuiteRunnerWorker.java:96)
at org.testng.TestNG.runSuitesSequentially(TestNG.java:1187)
at org.testng.TestNG.runSuitesLocally(TestNG.java:1109)
at org.testng.TestNG.runSuites(TestNG.java:1039)
at org.testng.TestNG.run(TestNG.java:1007)
at org.apache.maven.surefire.testng.TestNGExecutor.run(TestNGExecutor.java:77)
at org.apache.maven.surefire.testng.TestNGDirectoryTestSuite.executeMulti(TestNGDirectoryTestSuite.java:159)
at org.apache.maven.surefire.testng.TestNGDirectoryTestSuite.execute(TestNGDirectoryTestSuite.java:99)
at org.apache.maven.surefire.testng.TestNGProvider.invoke(TestNGProvider.java:106)
at java.base/jdk.internal.reflect.NativeMethodAccessorImpl.invoke0(Native Method)
at java.base/jdk.internal.reflect.NativeMethodAccessorImpl.invoke(NativeMethodAccessorImpl.java:62)
at java.base/jdk.internal.reflect.DelegatingMethodAccessorImpl.invoke(DelegatingMethodAccessorImpl.java:43)
at java.base/java.lang.reflect.Method.invoke(Method.java:566)
at org.apache.maven.surefire.util.ReflectionUtils.invokeMethodWithArray(ReflectionUtils.java:189)
at org.apache.maven.surefire.booter.ProviderFactory$ProviderProxy.invoke(ProviderFactory.java:165)
at org.apache.maven.surefire.booter.ProviderFactory.invokeProvider(ProviderFactory.java:85)
at org.apache.maven.surefire.booter.ForkedBooter.runSuitesInProcess(ForkedBooter.java:115)
at org.apache.maven.surefire.booter.ForkedBooter.main(ForkedBooter.java:75)
]]>
    </error>
  </testcase> <!-- testInsertWithEmptyModel -->
  <system-out/>
  <testcase classname="edu.poly.dao.NhanVienDaoNGTest" name="testFindByIdWithFound" time="0.035"/>
  <system-out/>
  <testcase classname="edu.poly.dao.NhanVienDaoNGTest" name="testUpdateWithNullModel" time="0.001"/>
  <system-out/>
  <testcase classname="edu.poly.dao.NhanVienDaoNGTest" name="testUpdateWithValidModel" time="0.001"/>
  <system-out/>
  <testcase classname="edu.poly.dao.NhanVienDaoNGTest" name="testInsertWithNullModel" time="0.005"/>
  <system-out/>
  <testcase classname="edu.poly.dao.NhanVienDaoNGTest" name="testSelect" time="0.004"/>
  <system-out/>
  <testcase classname="edu.poly.dao.NhanVienDaoNGTest" name="testUpdateWithEmptyModel" time="0.003">
    <error message="
Method NhanVienDaoNGTest.testUpdateWithEmptyModel()[pri:0, instance:edu.poly.dao.NhanVienDaoNGTest_$$_jvstabe_0@3ed03652] should have thrown an exception of type class java.lang.Exception" type="org.testng.TestException">
      <![CDATA[org.testng.TestException: 
Method NhanVienDaoNGTest.testUpdateWithEmptyModel()[pri:0, instance:edu.poly.dao.NhanVienDaoNGTest_$$_jvstabe_0@3ed03652] should have thrown an exception of type class java.lang.Exception
at org.testng.internal.ExpectedExceptionsHolder.noException(ExpectedExceptionsHolder.java:82)
at org.testng.internal.TestInvoker.considerExceptions(TestInvoker.java:741)
at org.testng.internal.TestInvoker.invokeMethod(TestInvoker.java:629)
at org.testng.internal.TestInvoker.invokeTestMethod(TestInvoker.java:173)
at org.testng.internal.MethodRunner.runInSequence(MethodRunner.java:46)
at org.testng.internal.TestInvoker$MethodInvocationAgent.invoke(TestInvoker.java:816)
at org.testng.internal.TestInvoker.invokeTestMethods(TestInvoker.java:146)
at org.testng.internal.TestMethodWorker.invokeTestMethods(TestMethodWorker.java:146)
at org.testng.internal.TestMethodWorker.run(TestMethodWorker.java:128)
at java.base/java.util.ArrayList.forEach(ArrayList.java:1540)
at org.testng.TestRunner.privateRun(TestRunner.java:766)
at org.testng.TestRunner.run(TestRunner.java:587)
at org.testng.SuiteRunner.runTest(SuiteRunner.java:384)
at org.testng.SuiteRunner.runSequentially(SuiteRunner.java:378)
at org.testng.SuiteRunner.privateRun(SuiteRunner.java:337)
at org.testng.SuiteRunner.run(SuiteRunner.java:286)
at org.testng.SuiteRunnerWorker.runSuite(SuiteRunnerWorker.java:53)
at org.testng.SuiteRunnerWorker.run(SuiteRunnerWorker.java:96)
at org.testng.TestNG.runSuitesSequentially(TestNG.java:1187)
at org.testng.TestNG.runSuitesLocally(TestNG.java:1109)
at org.testng.TestNG.runSuites(TestNG.java:1039)
at org.testng.TestNG.run(TestNG.java:1007)
at org.apache.maven.surefire.testng.TestNGExecutor.run(TestNGExecutor.java:77)
at org.apache.maven.surefire.testng.TestNGDirectoryTestSuite.executeMulti(TestNGDirectoryTestSuite.java:159)
at org.apache.maven.surefire.testng.TestNGDirectoryTestSuite.execute(TestNGDirectoryTestSuite.java:99)
at org.apache.maven.surefire.testng.TestNGProvider.invoke(TestNGProvider.java:106)
at java.base/jdk.internal.reflect.NativeMethodAccessorImpl.invoke0(Native Method)
at java.base/jdk.internal.reflect.NativeMethodAccessorImpl.invoke(NativeMethodAccessorImpl.java:62)
at java.base/jdk.internal.reflect.DelegatingMethodAccessorImpl.invoke(DelegatingMethodAccessorImpl.java:43)
at java.base/java.lang.reflect.Method.invoke(Method.java:566)
at org.apache.maven.surefire.util.ReflectionUtils.invokeMethodWithArray(ReflectionUtils.java:189)
at org.apache.maven.surefire.booter.ProviderFactory$ProviderProxy.invoke(ProviderFactory.java:165)
at org.apache.maven.surefire.booter.ProviderFactory.invokeProvider(ProviderFactory.java:85)
at org.apache.maven.surefire.booter.ForkedBooter.runSuitesInProcess(ForkedBooter.java:115)
at org.apache.maven.surefire.booter.ForkedBooter.main(ForkedBooter.java:75)
]]>
    </error>
  </testcase> <!-- testUpdateWithEmptyModel -->
  <system-out/>
  <testcase classname="edu.poly.dao.NhanVienDaoNGTest" name="testDeleteWithValidMahv" time="0.742"/>
  <system-out/>
</testsuite> <!-- edu.poly.dao.NhanVienDaoNGTest -->
